<?xml version="1.0" encoding="UTF-8"?>
<testng-results skipped="0" failed="2" total="5" passed="3">
  <reporter-output>
  </reporter-output>
  <suite name="Suite" duration-ms="12375" started-at="2016-01-04T11:12:11Z" finished-at="2016-01-04T11:12:23Z">
    <groups>
    </groups>
    <test name="Test" duration-ms="12375" started-at="2016-01-04T11:12:11Z" finished-at="2016-01-04T11:12:23Z">
      <class name="homepage.NewTest1">
        <test-method status="PASS" signature="f()[pri:0, instance:homepage.NewTest1@2cfb4a64]" name="f" duration-ms="12353" started-at="2016-01-04T16:42:11Z" finished-at="2016-01-04T16:42:23Z">
          <reporter-output>
          </reporter-output>
        </test-method> <!-- f -->
        <test-method status="FAIL" signature="f1()[pri:0, instance:homepage.NewTest1@2cfb4a64]" name="f1" duration-ms="3" started-at="2016-01-04T16:42:23Z" finished-at="2016-01-04T16:42:23Z">
          <exception class="java.lang.AssertionError">
            <message>
              <![CDATA[null]]>
            </message>
            <full-stacktrace>
              <![CDATA[java.lang.AssertionError: null
	at org.testng.Assert.fail(Assert.java:94)
	at org.testng.Assert.fail(Assert.java:101)
	at homepage.NewTest1.f1(NewTest1.java:28)
	at sun.reflect.NativeMethodAccessorImpl.invoke0(Native Method)
	at sun.reflect.NativeMethodAccessorImpl.invoke(Unknown Source)
	at sun.reflect.DelegatingMethodAccessorImpl.invoke(Unknown Source)
	at java.lang.reflect.Method.invoke(Unknown Source)
	at org.testng.internal.MethodInvocationHelper.invokeMethod(MethodInvocationHelper.java:85)
	at org.testng.internal.Invoker.invokeMethod(Invoker.java:639)
	at org.testng.internal.Invoker.invokeTestMethod(Invoker.java:816)
	at org.testng.internal.Invoker.invokeTestMethods(Invoker.java:1124)
	at org.testng.internal.TestMethodWorker.invokeTestMethods(TestMethodWorker.java:125)
	at org.testng.internal.TestMethodWorker.run(TestMethodWorker.java:108)
	at org.testng.TestRunner.privateRun(TestRunner.java:774)
	at org.testng.TestRunner.run(TestRunner.java:624)
	at org.testng.SuiteRunner.runTest(SuiteRunner.java:359)
	at org.testng.SuiteRunner.runSequentially(SuiteRunner.java:354)
	at org.testng.SuiteRunner.privateRun(SuiteRunner.java:312)
	at org.testng.SuiteRunner.run(SuiteRunner.java:261)
	at org.testng.SuiteRunnerWorker.runSuite(SuiteRunnerWorker.java:52)
	at org.testng.SuiteRunnerWorker.run(SuiteRunnerWorker.java:86)
	at org.testng.TestNG.runSuitesSequentially(TestNG.java:1191)
	at org.testng.TestNG.runSuitesLocally(TestNG.java:1116)
	at org.testng.TestNG.run(TestNG.java:1024)
	at org.testng.remote.RemoteTestNG.run(RemoteTestNG.java:112)
	at org.testng.remote.RemoteTestNG.initAndRun(RemoteTestNG.java:205)
	at org.testng.remote.RemoteTestNG.main(RemoteTestNG.java:176)
]]>
            </full-stacktrace>
          </exception> <!-- java.lang.AssertionError -->
          <reporter-output>
          </reporter-output>
        </test-method> <!-- f1 -->
        <test-method status="PASS" signature="f2()[pri:0, instance:homepage.NewTest1@2cfb4a64]" name="f2" duration-ms="1" started-at="2016-01-04T16:42:23Z" finished-at="2016-01-04T16:42:23Z">
          <reporter-output>
          </reporter-output>
        </test-method> <!-- f2 -->
      </class> <!-- homepage.NewTest1 -->
      <class name="homepage.NewTest2">
        <test-method status="PASS" signature="f()[pri:0, instance:homepage.NewTest2@2fc14f68]" name="f" duration-ms="0" started-at="2016-01-04T16:42:23Z" finished-at="2016-01-04T16:42:23Z">
          <reporter-output>
          </reporter-output>
        </test-method> <!-- f -->
        <test-method status="FAIL" signature="f1()[pri:0, instance:homepage.NewTest2@2fc14f68]" name="f1" duration-ms="1" started-at="2016-01-04T16:42:23Z" finished-at="2016-01-04T16:42:23Z">
          <exception class="java.lang.AssertionError">
            <message>
              <![CDATA[null]]>
            </message>
            <full-stacktrace>
              <![CDATA[java.lang.AssertionError: null
	at org.testng.Assert.fail(Assert.java:94)
	at org.testng.Assert.fail(Assert.java:101)
	at homepage.NewTest2.f1(NewTest2.java:59)
	at sun.reflect.NativeMethodAccessorImpl.invoke0(Native Method)
	at sun.reflect.NativeMethodAccessorImpl.invoke(Unknown Source)
	at sun.reflect.DelegatingMethodAccessorImpl.invoke(Unknown Source)
	at java.lang.reflect.Method.invoke(Unknown Source)
	at org.testng.internal.MethodInvocationHelper.invokeMethod(MethodInvocationHelper.java:85)
	at org.testng.internal.Invoker.invokeMethod(Invoker.java:639)
	at org.testng.internal.Invoker.invokeTestMethod(Invoker.java:816)
	at org.testng.internal.Invoker.invokeTestMethods(Invoker.java:1124)
	at org.testng.internal.TestMethodWorker.invokeTestMethods(TestMethodWorker.java:125)
	at org.testng.internal.TestMethodWorker.run(TestMethodWorker.java:108)
	at org.testng.TestRunner.privateRun(TestRunner.java:774)
	at org.testng.TestRunner.run(TestRunner.java:624)
	at org.testng.SuiteRunner.runTest(SuiteRunner.java:359)
	at org.testng.SuiteRunner.runSequentially(SuiteRunner.java:354)
	at org.testng.SuiteRunner.privateRun(SuiteRunner.java:312)
	at org.testng.SuiteRunner.run(SuiteRunner.java:261)
	at org.testng.SuiteRunnerWorker.runSuite(SuiteRunnerWorker.java:52)
	at org.testng.SuiteRunnerWorker.run(SuiteRunnerWorker.java:86)
	at org.testng.TestNG.runSuitesSequentially(TestNG.java:1191)
	at org.testng.TestNG.runSuitesLocally(TestNG.java:1116)
	at org.testng.TestNG.run(TestNG.java:1024)
	at org.testng.remote.RemoteTestNG.run(RemoteTestNG.java:112)
	at org.testng.remote.RemoteTestNG.initAndRun(RemoteTestNG.java:205)
	at org.testng.remote.RemoteTestNG.main(RemoteTestNG.java:176)
]]>
            </full-stacktrace>
          </exception> <!-- java.lang.AssertionError -->
          <reporter-output>
          </reporter-output>
        </test-method> <!-- f1 -->
      </class> <!-- homepage.NewTest2 -->
    </test> <!-- Test -->
  </suite> <!-- Suite -->
</testng-results>
